2025-04-18 16:03:08,056 - ERROR - Prueba de log: el logger está configurado correctamente.
2025-04-18 16:36:32,227 - ERROR - Prueba de log: el logger está configurado correctamente.
2025-04-18 16:36:35,156 - ERROR - Excepción no manejada
Traceback (most recent call last):
  File "c:\Users\PC\Desktop\VSC\DATKit\.conda\Lib\site-packages\pandas\compat\_optional.py", line 135, in import_optional_dependency
    module = importlib.import_module(name)
             ^^^^^^^^^^^^^^^^^^^^^^^^^^^^^
  File "c:\Users\PC\Desktop\VSC\DATKit\.conda\Lib\importlib\__init__.py", line 90, in import_module
    return _bootstrap._gcd_import(name[level:], package, level)
           ^^^^^^^^^^^^^^^^^^^^^^^^^^^^^^^^^^^^^^^^^^^^^^^^^^^^
  File "<frozen importlib._bootstrap>", line 1387, in _gcd_import
  File "<frozen importlib._bootstrap>", line 1360, in _find_and_load
  File "<frozen importlib._bootstrap>", line 1324, in _find_and_load_unlocked
ModuleNotFoundError: No module named 'openpyxl'

During handling of the above exception, another exception occurred:

Traceback (most recent call last):
  File "<frozen runpy>", line 198, in _run_module_as_main
  File "<frozen runpy>", line 88, in _run_code
  File "C:\Users\PC\Desktop\VSC\DATKit\demo\example_process.py", line 52, in <module>
    df_list = load_data(CSV_list, CSV_format_list)
              ^^^^^^^^^^^^^^^^^^^^^^^^^^^^^^^^^^^^
  File "C:\Users\PC\Desktop\VSC\DATKit\DATKit\data_loading.py", line 49, in load_data
    df = pd.read_excel(base_file_name, sheet_name=sheet_name, decimal=format_element['decimal'])
         ^^^^^^^^^^^^^^^^^^^^^^^^^^^^^^^^^^^^^^^^^^^^^^^^^^^^^^^^^^^^^^^^^^^^^^^^^^^^^^^^^^^^^^^
  File "c:\Users\PC\Desktop\VSC\DATKit\.conda\Lib\site-packages\pandas\io\excel\_base.py", line 495, in read_excel
    io = ExcelFile(
         ^^^^^^^^^^
  File "c:\Users\PC\Desktop\VSC\DATKit\.conda\Lib\site-packages\pandas\io\excel\_base.py", line 1567, in __init__
    self._reader = self._engines[engine](
                   ^^^^^^^^^^^^^^^^^^^^^^
  File "c:\Users\PC\Desktop\VSC\DATKit\.conda\Lib\site-packages\pandas\io\excel\_openpyxl.py", line 552, in __init__
    import_optional_dependency("openpyxl")
  File "c:\Users\PC\Desktop\VSC\DATKit\.conda\Lib\site-packages\pandas\compat\_optional.py", line 138, in import_optional_dependency
    raise ImportError(msg)
ImportError: Missing optional dependency 'openpyxl'.  Use pip or conda to install openpyxl.
2025-04-18 16:37:29,251 - ERROR - Prueba de log: el logger está configurado correctamente.
2025-04-18 16:37:31,945 - ERROR - Excepción no manejada
Traceback (most recent call last):
  File "c:\Users\PC\Desktop\VSC\DATKit\.conda\Lib\site-packages\pandas\compat\_optional.py", line 135, in import_optional_dependency
    module = importlib.import_module(name)
             ^^^^^^^^^^^^^^^^^^^^^^^^^^^^^
  File "c:\Users\PC\Desktop\VSC\DATKit\.conda\Lib\importlib\__init__.py", line 90, in import_module
    return _bootstrap._gcd_import(name[level:], package, level)
           ^^^^^^^^^^^^^^^^^^^^^^^^^^^^^^^^^^^^^^^^^^^^^^^^^^^^
  File "<frozen importlib._bootstrap>", line 1387, in _gcd_import
  File "<frozen importlib._bootstrap>", line 1360, in _find_and_load
  File "<frozen importlib._bootstrap>", line 1324, in _find_and_load_unlocked
ModuleNotFoundError: No module named 'openpyxl'

During handling of the above exception, another exception occurred:

Traceback (most recent call last):
  File "<frozen runpy>", line 198, in _run_module_as_main
  File "<frozen runpy>", line 88, in _run_code
  File "C:\Users\PC\Desktop\VSC\DATKit\demo\example_process.py", line 52, in <module>
    df_list = load_data(CSV_list, CSV_format_list)
              ^^^^^^^^^^^^^^^^^^^^^^^^^^^^^^^^^^^^
  File "C:\Users\PC\Desktop\VSC\DATKit\DATKit\data_loading.py", line 49, in load_data
    df = pd.read_excel(base_file_name, sheet_name=sheet_name, decimal=format_element['decimal'])
         ^^^^^^^^^^^^^^^^^^^^^^^^^^^^^^^^^^^^^^^^^^^^^^^^^^^^^^^^^^^^^^^^^^^^^^^^^^^^^^^^^^^^^^^
  File "c:\Users\PC\Desktop\VSC\DATKit\.conda\Lib\site-packages\pandas\io\excel\_base.py", line 495, in read_excel
    io = ExcelFile(
         ^^^^^^^^^^
  File "c:\Users\PC\Desktop\VSC\DATKit\.conda\Lib\site-packages\pandas\io\excel\_base.py", line 1567, in __init__
    self._reader = self._engines[engine](
                   ^^^^^^^^^^^^^^^^^^^^^^
  File "c:\Users\PC\Desktop\VSC\DATKit\.conda\Lib\site-packages\pandas\io\excel\_openpyxl.py", line 552, in __init__
    import_optional_dependency("openpyxl")
  File "c:\Users\PC\Desktop\VSC\DATKit\.conda\Lib\site-packages\pandas\compat\_optional.py", line 138, in import_optional_dependency
    raise ImportError(msg)
ImportError: Missing optional dependency 'openpyxl'.  Use pip or conda to install openpyxl.
2025-04-18 16:46:10,816 - ERROR - Prueba de log: el logger está configurado correctamente.
2025-04-18 16:46:14,100 - ERROR - Excepción no manejada
Traceback (most recent call last):
  File "<frozen runpy>", line 198, in _run_module_as_main
  File "<frozen runpy>", line 88, in _run_code
  File "C:\Users\PC\Desktop\VSC\DATKit\demo\example_process.py", line 75, in <module>
    generate_linechart(filtered_df,
TypeError: generate_linechart() got an unexpected keyword argument 'name'
2025-04-18 16:47:22,635 - ERROR - Prueba de log: el logger está configurado correctamente.
2025-04-18 16:47:25,571 - ERROR - Excepción no manejada
Traceback (most recent call last):
  File "<frozen runpy>", line 198, in _run_module_as_main
  File "<frozen runpy>", line 88, in _run_code
  File "C:\Users\PC\Desktop\VSC\DATKit\demo\example_process.py", line 75, in <module>
    generate_linechart(filtered_df,
TypeError: generate_linechart() got an unexpected keyword argument 'name'
2025-04-18 16:47:47,521 - ERROR - Prueba de log: el logger está configurado correctamente.
2025-04-18 16:47:51,411 - ERROR - Excepción no manejada
Traceback (most recent call last):
  File "<frozen runpy>", line 198, in _run_module_as_main
  File "<frozen runpy>", line 88, in _run_code
  File "C:\Users\PC\Desktop\VSC\DATKit\demo\example_process.py", line 75, in <module>
    generate_linechart(filtered_df,
  File "C:\Users\PC\Desktop\VSC\DATKit\DATKit\data_visualization.py", line 27, in generate_linechart
    plot_linechart(spectra, x, names, name=filename)
  File "C:\Users\PC\Desktop\VSC\DATKit\DATKit\tools\chart_tools.py", line 36, in plot_linechart
    plt.plot(x, spectra[i], label=element_name, **kwargs)
  File "c:\Users\PC\Desktop\VSC\DATKit\.conda\Lib\site-packages\matplotlib\pyplot.py", line 3827, in plot
    return gca().plot(
           ^^^^^^^^^^^
  File "c:\Users\PC\Desktop\VSC\DATKit\.conda\Lib\site-packages\matplotlib\axes\_axes.py", line 1777, in plot
    lines = [*self._get_lines(self, *args, data=data, **kwargs)]
            ^^^^^^^^^^^^^^^^^^^^^^^^^^^^^^^^^^^^^^^^^^^^^^^^^^^^
  File "c:\Users\PC\Desktop\VSC\DATKit\.conda\Lib\site-packages\matplotlib\axes\_base.py", line 297, in __call__
    yield from self._plot_args(
               ^^^^^^^^^^^^^^^^
  File "c:\Users\PC\Desktop\VSC\DATKit\.conda\Lib\site-packages\matplotlib\axes\_base.py", line 546, in _plot_args
    return [l[0] for l in result]
                          ^^^^^^
  File "c:\Users\PC\Desktop\VSC\DATKit\.conda\Lib\site-packages\matplotlib\axes\_base.py", line 539, in <genexpr>
    result = (make_artist(axes, x[:, j % ncx], y[:, j % ncy], kw,
              ^^^^^^^^^^^^^^^^^^^^^^^^^^^^^^^^^^^^^^^^^^^^^^^^^^^
  File "c:\Users\PC\Desktop\VSC\DATKit\.conda\Lib\site-packages\matplotlib\axes\_base.py", line 338, in _make_line
    seg = mlines.Line2D(x, y, **kw)
          ^^^^^^^^^^^^^^^^^^^^^^^^^
  File "c:\Users\PC\Desktop\VSC\DATKit\.conda\Lib\site-packages\matplotlib\lines.py", line 407, in __init__
    self._internal_update(kwargs)
  File "c:\Users\PC\Desktop\VSC\DATKit\.conda\Lib\site-packages\matplotlib\artist.py", line 1233, in _internal_update
    return self._update_props(
           ^^^^^^^^^^^^^^^^^^^
  File "c:\Users\PC\Desktop\VSC\DATKit\.conda\Lib\site-packages\matplotlib\artist.py", line 1206, in _update_props
    raise AttributeError(
AttributeError: Line2D.set() got an unexpected keyword argument 'name'
2025-04-18 16:52:50,360 - ERROR - Prueba de log: el logger está configurado correctamente.
2025-04-18 16:52:53,537 - ERROR - Excepción no manejada
Traceback (most recent call last):
  File "<frozen runpy>", line 198, in _run_module_as_main
  File "<frozen runpy>", line 88, in _run_code
  File "C:\Users\PC\Desktop\VSC\DATKit\demo\example_process.py", line 75, in <module>
    generate_linechart(filtered_df,
  File "C:\Users\PC\Desktop\VSC\DATKit\DATKit\data_visualization.py", line 27, in generate_linechart
    plot_linechart(spectra, x, names, name=filename)
  File "C:\Users\PC\Desktop\VSC\DATKit\DATKit\tools\chart_tools.py", line 36, in plot_linechart
    plt.plot(x, spectra[i], label=element_name, **kwargs)
  File "c:\Users\PC\Desktop\VSC\DATKit\.conda\Lib\site-packages\matplotlib\pyplot.py", line 3827, in plot
    return gca().plot(
           ^^^^^^^^^^^
  File "c:\Users\PC\Desktop\VSC\DATKit\.conda\Lib\site-packages\matplotlib\axes\_axes.py", line 1777, in plot
    lines = [*self._get_lines(self, *args, data=data, **kwargs)]
            ^^^^^^^^^^^^^^^^^^^^^^^^^^^^^^^^^^^^^^^^^^^^^^^^^^^^
  File "c:\Users\PC\Desktop\VSC\DATKit\.conda\Lib\site-packages\matplotlib\axes\_base.py", line 297, in __call__
    yield from self._plot_args(
               ^^^^^^^^^^^^^^^^
  File "c:\Users\PC\Desktop\VSC\DATKit\.conda\Lib\site-packages\matplotlib\axes\_base.py", line 546, in _plot_args
    return [l[0] for l in result]
                          ^^^^^^
  File "c:\Users\PC\Desktop\VSC\DATKit\.conda\Lib\site-packages\matplotlib\axes\_base.py", line 539, in <genexpr>
    result = (make_artist(axes, x[:, j % ncx], y[:, j % ncy], kw,
              ^^^^^^^^^^^^^^^^^^^^^^^^^^^^^^^^^^^^^^^^^^^^^^^^^^^
  File "c:\Users\PC\Desktop\VSC\DATKit\.conda\Lib\site-packages\matplotlib\axes\_base.py", line 338, in _make_line
    seg = mlines.Line2D(x, y, **kw)
          ^^^^^^^^^^^^^^^^^^^^^^^^^
  File "c:\Users\PC\Desktop\VSC\DATKit\.conda\Lib\site-packages\matplotlib\lines.py", line 407, in __init__
    self._internal_update(kwargs)
  File "c:\Users\PC\Desktop\VSC\DATKit\.conda\Lib\site-packages\matplotlib\artist.py", line 1233, in _internal_update
    return self._update_props(
           ^^^^^^^^^^^^^^^^^^^
  File "c:\Users\PC\Desktop\VSC\DATKit\.conda\Lib\site-packages\matplotlib\artist.py", line 1206, in _update_props
    raise AttributeError(
AttributeError: Line2D.set() got an unexpected keyword argument 'name'
2025-04-18 16:53:33,154 - ERROR - Prueba de log: el logger está configurado correctamente.
