2024-12-18 21:30:11,309 - ERROR - Prueba de log: el logger está configurado correctamente.
2024-12-18 21:33:15,763 - ERROR - Prueba de log: el logger está configurado correctamente.
2024-12-18 21:33:15,763 - ERROR - Excepción no manejada
Traceback (most recent call last):
  File "C:\Users\ignac\PycharmProjects\TAUP-DATKit\TAUP_DATKit\Demo\example_process.py", line 1, in <module>
    from TAUP_DATKit.Properties.process_prop_loader import config_process
  File "C:\Users\ignac\PycharmProjects\TAUP-DATKit\TAUP_DATKit\__init__.py", line 44, in <module>
    HOLA
NameError: name 'HOLA' is not defined
2024-12-19 09:48:55,896 - ERROR - Prueba de log: el logger está configurado correctamente.
2024-12-19 09:48:55,958 - ERROR - Excepción no manejada
Traceback (most recent call last):
  File "C:\Users\igmarco\PycharmProjects\TAUP-DATKit\TAUP_DATKit\Demo\example_process.py", line 3, in <module>
    from TAUP_DATKit.analysis_reporting import generate_pdf_report
  File "C:\Users\igmarco\PycharmProjects\TAUP-DATKit\TAUP_DATKit\analysis_reporting.py", line 1, in <module>
    from reportlab.lib.pagesizes import letter
ModuleNotFoundError: No module named 'reportlab'
2024-12-19 09:49:21,660 - ERROR - Prueba de log: el logger está configurado correctamente.
2024-12-19 09:49:22,587 - ERROR - Excepción no manejada
Traceback (most recent call last):
  File "C:\Users\igmarco\PycharmProjects\TAUP-DATKit\TAUP_DATKit\Demo\example_process.py", line 3, in <module>
    from TAUP_DATKit.analysis_reporting import generate_pdf_report
  File "C:\Users\igmarco\PycharmProjects\TAUP-DATKit\TAUP_DATKit\analysis_reporting.py", line 5, in <module>
    from TAUP_DATKit.Utils.image_utils import convert_svg_to_png
  File "C:\Users\igmarco\PycharmProjects\TAUP-DATKit\TAUP_DATKit\Utils\image_utils.py", line 1, in <module>
    import cairosvg
  File "C:\Users\igmarco\PycharmProjects\TAUP-DATKit\venv\lib\site-packages\cairosvg\__init__.py", line 26, in <module>
    from . import surface  # noqa isort:skip
  File "C:\Users\igmarco\PycharmProjects\TAUP-DATKit\venv\lib\site-packages\cairosvg\surface.py", line 9, in <module>
    import cairocffi as cairo
  File "C:\Users\igmarco\PycharmProjects\TAUP-DATKit\venv\lib\site-packages\cairocffi\__init__.py", line 60, in <module>
    cairo = dlopen(
  File "C:\Users\igmarco\PycharmProjects\TAUP-DATKit\venv\lib\site-packages\cairocffi\__init__.py", line 57, in dlopen
    raise OSError(error_message)  # pragma: no cover
OSError: no library called "cairo-2" was found
no library called "cairo" was found
no library called "libcairo-2" was found
cannot load library 'libcairo.so.2': error 0x7e.  Additionally, ctypes.util.find_library() did not manage to locate a library called 'libcairo.so.2'
cannot load library 'libcairo.2.dylib': error 0x7e.  Additionally, ctypes.util.find_library() did not manage to locate a library called 'libcairo.2.dylib'
cannot load library 'libcairo-2.dll': error 0x7e.  Additionally, ctypes.util.find_library() did not manage to locate a library called 'libcairo-2.dll'
2024-12-19 09:50:26,758 - ERROR - Prueba de log: el logger está configurado correctamente.
2024-12-19 09:50:27,340 - ERROR - Excepción no manejada
Traceback (most recent call last):
  File "C:\Users\igmarco\PycharmProjects\TAUP-DATKit\TAUP_DATKit\Demo\example_process.py", line 3, in <module>
    from TAUP_DATKit.analysis_reporting import generate_pdf_report
  File "C:\Users\igmarco\PycharmProjects\TAUP-DATKit\TAUP_DATKit\analysis_reporting.py", line 5, in <module>
    from TAUP_DATKit.Utils.image_utils import convert_svg_to_png
  File "C:\Users\igmarco\PycharmProjects\TAUP-DATKit\TAUP_DATKit\Utils\image_utils.py", line 1, in <module>
    import cairosvg
  File "C:\Users\igmarco\PycharmProjects\TAUP-DATKit\venv\lib\site-packages\cairosvg\__init__.py", line 26, in <module>
    from . import surface  # noqa isort:skip
  File "C:\Users\igmarco\PycharmProjects\TAUP-DATKit\venv\lib\site-packages\cairosvg\surface.py", line 9, in <module>
    import cairocffi as cairo
  File "C:\Users\igmarco\PycharmProjects\TAUP-DATKit\venv\lib\site-packages\cairocffi\__init__.py", line 60, in <module>
    cairo = dlopen(
  File "C:\Users\igmarco\PycharmProjects\TAUP-DATKit\venv\lib\site-packages\cairocffi\__init__.py", line 57, in dlopen
    raise OSError(error_message)  # pragma: no cover
OSError: no library called "cairo-2" was found
no library called "cairo" was found
no library called "libcairo-2" was found
cannot load library 'libcairo.so.2': error 0x7e.  Additionally, ctypes.util.find_library() did not manage to locate a library called 'libcairo.so.2'
cannot load library 'libcairo.2.dylib': error 0x7e.  Additionally, ctypes.util.find_library() did not manage to locate a library called 'libcairo.2.dylib'
cannot load library 'libcairo-2.dll': error 0x7e.  Additionally, ctypes.util.find_library() did not manage to locate a library called 'libcairo-2.dll'
2024-12-19 09:52:52,061 - ERROR - Prueba de log: el logger está configurado correctamente.
2024-12-19 09:52:52,628 - ERROR - Excepción no manejada
Traceback (most recent call last):
  File "C:\Users\igmarco\PycharmProjects\TAUP-DATKit\TAUP_DATKit\Demo\example_process.py", line 3, in <module>
    from TAUP_DATKit.analysis_reporting import generate_pdf_report
  File "C:\Users\igmarco\PycharmProjects\TAUP-DATKit\TAUP_DATKit\analysis_reporting.py", line 5, in <module>
    from TAUP_DATKit.Utils.image_utils import convert_svg_to_png
  File "C:\Users\igmarco\PycharmProjects\TAUP-DATKit\TAUP_DATKit\Utils\image_utils.py", line 1, in <module>
    import cairosvg
  File "C:\Users\igmarco\PycharmProjects\TAUP-DATKit\venv\lib\site-packages\cairosvg\__init__.py", line 26, in <module>
    from . import surface  # noqa isort:skip
  File "C:\Users\igmarco\PycharmProjects\TAUP-DATKit\venv\lib\site-packages\cairosvg\surface.py", line 9, in <module>
    import cairocffi as cairo
  File "C:\Users\igmarco\PycharmProjects\TAUP-DATKit\venv\lib\site-packages\cairocffi\__init__.py", line 60, in <module>
    cairo = dlopen(
  File "C:\Users\igmarco\PycharmProjects\TAUP-DATKit\venv\lib\site-packages\cairocffi\__init__.py", line 57, in dlopen
    raise OSError(error_message)  # pragma: no cover
OSError: no library called "cairo-2" was found
no library called "cairo" was found
no library called "libcairo-2" was found
cannot load library 'libcairo.so.2': error 0x7e.  Additionally, ctypes.util.find_library() did not manage to locate a library called 'libcairo.so.2'
cannot load library 'libcairo.2.dylib': error 0x7e.  Additionally, ctypes.util.find_library() did not manage to locate a library called 'libcairo.2.dylib'
cannot load library 'libcairo-2.dll': error 0x7e.  Additionally, ctypes.util.find_library() did not manage to locate a library called 'libcairo-2.dll'
2024-12-19 10:12:14,994 - ERROR - Prueba de log: el logger está configurado correctamente.
2024-12-19 10:12:15,590 - ERROR - Excepción no manejada
Traceback (most recent call last):
  File "C:\Users\igmarco\PycharmProjects\TAUP-DATKit\TAUP_DATKit\Demo\example_process.py", line 3, in <module>
    from TAUP_DATKit.analysis_reporting import generate_pdf_report
  File "C:\Users\igmarco\PycharmProjects\TAUP-DATKit\TAUP_DATKit\analysis_reporting.py", line 5, in <module>
    from TAUP_DATKit.Utils.image_utils import convert_svg_to_png
  File "C:\Users\igmarco\PycharmProjects\TAUP-DATKit\TAUP_DATKit\Utils\image_utils.py", line 1, in <module>
    import cairosvg
  File "C:\Users\igmarco\PycharmProjects\TAUP-DATKit\venv\lib\site-packages\cairosvg\__init__.py", line 26, in <module>
    from . import surface  # noqa isort:skip
  File "C:\Users\igmarco\PycharmProjects\TAUP-DATKit\venv\lib\site-packages\cairosvg\surface.py", line 9, in <module>
    import cairocffi as cairo
  File "C:\Users\igmarco\PycharmProjects\TAUP-DATKit\venv\lib\site-packages\cairocffi\__init__.py", line 60, in <module>
    cairo = dlopen(
  File "C:\Users\igmarco\PycharmProjects\TAUP-DATKit\venv\lib\site-packages\cairocffi\__init__.py", line 57, in dlopen
    raise OSError(error_message)  # pragma: no cover
OSError: no library called "cairo-2" was found
no library called "cairo" was found
no library called "libcairo-2" was found
cannot load library 'libcairo.so.2': error 0x7e.  Additionally, ctypes.util.find_library() did not manage to locate a library called 'libcairo.so.2'
cannot load library 'libcairo.2.dylib': error 0x7e.  Additionally, ctypes.util.find_library() did not manage to locate a library called 'libcairo.2.dylib'
cannot load library 'libcairo-2.dll': error 0x7e.  Additionally, ctypes.util.find_library() did not manage to locate a library called 'libcairo-2.dll'
2024-12-19 10:14:34,859 - ERROR - Prueba de log: el logger está configurado correctamente.
2024-12-19 10:14:35,190 - ERROR - Excepción no manejada
Traceback (most recent call last):
  File "C:\Users\igmarco\PycharmProjects\TAUP-DATKit\venv\lib\site-packages\pyvips\__init__.py", line 19, in <module>
    import _libvips
ModuleNotFoundError: No module named '_libvips'

During handling of the above exception, another exception occurred:

Traceback (most recent call last):
  File "C:\Users\igmarco\PycharmProjects\TAUP-DATKit\TAUP_DATKit\Demo\example_process.py", line 3, in <module>
    from TAUP_DATKit.analysis_reporting import generate_pdf_report
  File "C:\Users\igmarco\PycharmProjects\TAUP-DATKit\TAUP_DATKit\analysis_reporting.py", line 5, in <module>
    from TAUP_DATKit.Utils.image_utils import convert_svg_to_png
  File "C:\Users\igmarco\PycharmProjects\TAUP-DATKit\TAUP_DATKit\Utils\image_utils.py", line 1, in <module>
    import pyvips
  File "C:\Users\igmarco\PycharmProjects\TAUP-DATKit\venv\lib\site-packages\pyvips\__init__.py", line 57, in <module>
    vips_lib = ffi.dlopen('libvips-42.dll')
  File "C:\Users\igmarco\PycharmProjects\TAUP-DATKit\venv\lib\site-packages\cffi\api.py", line 150, in dlopen
    lib, function_cache = _make_ffi_library(self, name, flags)
  File "C:\Users\igmarco\PycharmProjects\TAUP-DATKit\venv\lib\site-packages\cffi\api.py", line 834, in _make_ffi_library
    backendlib = _load_backend_lib(backend, libname, flags)
  File "C:\Users\igmarco\PycharmProjects\TAUP-DATKit\venv\lib\site-packages\cffi\api.py", line 829, in _load_backend_lib
    raise OSError(msg)
OSError: cannot load library 'libvips-42.dll': error 0x7e.  Additionally, ctypes.util.find_library() did not manage to locate a library called 'libvips-42.dll'
2024-12-19 10:21:44,498 - ERROR - Prueba de log: el logger está configurado correctamente.
2024-12-19 10:21:45,070 - ERROR - Excepción no manejada
Traceback (most recent call last):
  File "C:\Users\igmarco\PycharmProjects\TAUP-DATKit\venv\lib\site-packages\wand\api.py", line 159, in <module>
    libraries = load_library()
  File "C:\Users\igmarco\PycharmProjects\TAUP-DATKit\venv\lib\site-packages\wand\api.py", line 148, in load_library
    raise IOError('cannot find library; tried paths: ' + repr(tried_paths))
OSError: cannot find library; tried paths: []

During handling of the above exception, another exception occurred:

Traceback (most recent call last):
  File "C:\Users\igmarco\PycharmProjects\TAUP-DATKit\TAUP_DATKit\Demo\example_process.py", line 3, in <module>
    from TAUP_DATKit.analysis_reporting import generate_pdf_report
  File "C:\Users\igmarco\PycharmProjects\TAUP-DATKit\TAUP_DATKit\analysis_reporting.py", line 5, in <module>
    from TAUP_DATKit.Utils.image_utils import convert_svg_to_png
  File "C:\Users\igmarco\PycharmProjects\TAUP-DATKit\TAUP_DATKit\Utils\image_utils.py", line 1, in <module>
    from wand.api import library
  File "C:\Users\igmarco\PycharmProjects\TAUP-DATKit\venv\lib\site-packages\wand\api.py", line 183, in <module>
    raise ImportError('MagickWand shared library not found.\n'
ImportError: MagickWand shared library not found.
You probably had not installed ImageMagick library.
Try to install:
  https://docs.wand-py.org/en/latest/guide/install.html#install-imagemagick-on-windows
2024-12-19 10:32:29,458 - ERROR - Prueba de log: el logger está configurado correctamente.
2024-12-19 10:32:29,946 - ERROR - Excepción no manejada
Traceback (most recent call last):
  File "C:\Users\igmarco\PycharmProjects\TAUP-DATKit\TAUP_DATKit\Demo\example_process.py", line 3, in <module>
    from TAUP_DATKit.analysis_reporting import generate_pdf_report
  File "C:\Users\igmarco\PycharmProjects\TAUP-DATKit\TAUP_DATKit\analysis_reporting.py", line 5, in <module>
    from TAUP_DATKit.Utils.image_utils import convert_svg_to_png
  File "C:\Users\igmarco\PycharmProjects\TAUP-DATKit\TAUP_DATKit\Utils\image_utils.py", line 61, in <module>
    import cairosvg
  File "C:\Users\igmarco\PycharmProjects\TAUP-DATKit\venv\lib\site-packages\cairosvg\__init__.py", line 26, in <module>
    from . import surface  # noqa isort:skip
  File "C:\Users\igmarco\PycharmProjects\TAUP-DATKit\venv\lib\site-packages\cairosvg\surface.py", line 9, in <module>
    import cairocffi as cairo
  File "C:\Users\igmarco\PycharmProjects\TAUP-DATKit\venv\lib\site-packages\cairocffi\__init__.py", line 60, in <module>
    cairo = dlopen(
  File "C:\Users\igmarco\PycharmProjects\TAUP-DATKit\venv\lib\site-packages\cairocffi\__init__.py", line 57, in dlopen
    raise OSError(error_message)  # pragma: no cover
OSError: no library called "cairo-2" was found
no library called "cairo" was found
no library called "libcairo-2" was found
cannot load library 'libcairo.so.2': error 0x7e.  Additionally, ctypes.util.find_library() did not manage to locate a library called 'libcairo.so.2'
cannot load library 'libcairo.2.dylib': error 0x7e.  Additionally, ctypes.util.find_library() did not manage to locate a library called 'libcairo.2.dylib'
cannot load library 'libcairo-2.dll': error 0x7e.  Additionally, ctypes.util.find_library() did not manage to locate a library called 'libcairo-2.dll'
2024-12-19 10:38:13,327 - ERROR - Prueba de log: el logger está configurado correctamente.
2024-12-19 10:38:13,634 - ERROR - Excepción no manejada
Traceback (most recent call last):
  File "C:\Users\igmarco\PycharmProjects\TAUP-DATKit\venv\lib\site-packages\pyvips\__init__.py", line 19, in <module>
    import _libvips
ModuleNotFoundError: No module named '_libvips'

During handling of the above exception, another exception occurred:

Traceback (most recent call last):
  File "C:\Users\igmarco\PycharmProjects\TAUP-DATKit\TAUP_DATKit\Demo\example_process.py", line 3, in <module>
    from TAUP_DATKit.analysis_reporting import generate_pdf_report
  File "C:\Users\igmarco\PycharmProjects\TAUP-DATKit\TAUP_DATKit\analysis_reporting.py", line 5, in <module>
    from TAUP_DATKit.Utils.image_utils import convert_svg_to_png
  File "C:\Users\igmarco\PycharmProjects\TAUP-DATKit\TAUP_DATKit\Utils\image_utils.py", line 36, in <module>
    import pyvips
  File "C:\Users\igmarco\PycharmProjects\TAUP-DATKit\venv\lib\site-packages\pyvips\__init__.py", line 57, in <module>
    vips_lib = ffi.dlopen('libvips-42.dll')
  File "C:\Users\igmarco\PycharmProjects\TAUP-DATKit\venv\lib\site-packages\cffi\api.py", line 150, in dlopen
    lib, function_cache = _make_ffi_library(self, name, flags)
  File "C:\Users\igmarco\PycharmProjects\TAUP-DATKit\venv\lib\site-packages\cffi\api.py", line 834, in _make_ffi_library
    backendlib = _load_backend_lib(backend, libname, flags)
  File "C:\Users\igmarco\PycharmProjects\TAUP-DATKit\venv\lib\site-packages\cffi\api.py", line 829, in _load_backend_lib
    raise OSError(msg)
OSError: cannot load library 'libvips-42.dll': error 0x7e.  Additionally, ctypes.util.find_library() did not manage to locate a library called 'libvips-42.dll'
2024-12-19 10:40:10,783 - ERROR - Prueba de log: el logger está configurado correctamente.
2024-12-19 10:40:11,037 - ERROR - Excepción no manejada
Traceback (most recent call last):
  File "C:\Users\igmarco\PycharmProjects\TAUP-DATKit\TAUP_DATKit\Demo\example_process.py", line 3, in <module>
    from TAUP_DATKit.analysis_reporting import generate_pdf_report
  File "C:\Users\igmarco\PycharmProjects\TAUP-DATKit\TAUP_DATKit\analysis_reporting.py", line 5, in <module>
    from TAUP_DATKit.Utils.image_utils import convert_svg_to_png
  File "C:\Users\igmarco\PycharmProjects\TAUP-DATKit\TAUP_DATKit\Utils\image_utils.py", line 5, in <module>
    add_dll_dir(vipsbin)
  File "C:\Users\igmarco\AppData\Local\Programs\Python\Python39\lib\os.py", line 1111, in add_dll_directory
    cookie = nt._add_dll_directory(path)
FileNotFoundError: [WinError 3] El sistema no puede encontrar la ruta especificada: 'c:\\vips-dev-8.7\\bin'
2024-12-19 10:43:10,260 - ERROR - Prueba de log: el logger está configurado correctamente.
2024-12-19 10:43:10,663 - ERROR - Excepción no manejada
Traceback (most recent call last):
  File "C:\Users\igmarco\PycharmProjects\TAUP-DATKit\venv\lib\site-packages\pyvips\__init__.py", line 19, in <module>
    import _libvips
ModuleNotFoundError: No module named '_libvips'

During handling of the above exception, another exception occurred:

Traceback (most recent call last):
  File "C:\Users\igmarco\PycharmProjects\TAUP-DATKit\TAUP_DATKit\Demo\example_process.py", line 3, in <module>
    from TAUP_DATKit.analysis_reporting import generate_pdf_report
  File "C:\Users\igmarco\PycharmProjects\TAUP-DATKit\TAUP_DATKit\analysis_reporting.py", line 5, in <module>
    from TAUP_DATKit.Utils.image_utils import convert_svg_to_png
  File "C:\Users\igmarco\PycharmProjects\TAUP-DATKit\TAUP_DATKit\Utils\image_utils.py", line 1, in <module>
    import pyvips
  File "C:\Users\igmarco\PycharmProjects\TAUP-DATKit\venv\lib\site-packages\pyvips\__init__.py", line 57, in <module>
    vips_lib = ffi.dlopen('libvips-42.dll')
  File "C:\Users\igmarco\PycharmProjects\TAUP-DATKit\venv\lib\site-packages\cffi\api.py", line 150, in dlopen
    lib, function_cache = _make_ffi_library(self, name, flags)
  File "C:\Users\igmarco\PycharmProjects\TAUP-DATKit\venv\lib\site-packages\cffi\api.py", line 834, in _make_ffi_library
    backendlib = _load_backend_lib(backend, libname, flags)
  File "C:\Users\igmarco\PycharmProjects\TAUP-DATKit\venv\lib\site-packages\cffi\api.py", line 829, in _load_backend_lib
    raise OSError(msg)
OSError: cannot load library 'libvips-42.dll': error 0x7e.  Additionally, ctypes.util.find_library() did not manage to locate a library called 'libvips-42.dll'
2024-12-19 10:46:41,532 - ERROR - Prueba de log: el logger está configurado correctamente.
2024-12-19 10:46:41,901 - ERROR - Excepción no manejada
Traceback (most recent call last):
  File "C:\Users\igmarco\PycharmProjects\TAUP-DATKit\venv\lib\site-packages\pyvips\__init__.py", line 19, in <module>
    import _libvips
ModuleNotFoundError: No module named '_libvips'

During handling of the above exception, another exception occurred:

Traceback (most recent call last):
  File "C:\Users\igmarco\PycharmProjects\TAUP-DATKit\TAUP_DATKit\Demo\example_process.py", line 3, in <module>
    from TAUP_DATKit.analysis_reporting import generate_pdf_report
  File "C:\Users\igmarco\PycharmProjects\TAUP-DATKit\TAUP_DATKit\analysis_reporting.py", line 5, in <module>
    from TAUP_DATKit.Utils.image_utils import convert_svg_to_png
  File "C:\Users\igmarco\PycharmProjects\TAUP-DATKit\TAUP_DATKit\Utils\image_utils.py", line 9, in <module>
    import pyvips
  File "C:\Users\igmarco\PycharmProjects\TAUP-DATKit\venv\lib\site-packages\pyvips\__init__.py", line 57, in <module>
    vips_lib = ffi.dlopen('libvips-42.dll')
  File "C:\Users\igmarco\PycharmProjects\TAUP-DATKit\venv\lib\site-packages\cffi\api.py", line 150, in dlopen
    lib, function_cache = _make_ffi_library(self, name, flags)
  File "C:\Users\igmarco\PycharmProjects\TAUP-DATKit\venv\lib\site-packages\cffi\api.py", line 834, in _make_ffi_library
    backendlib = _load_backend_lib(backend, libname, flags)
  File "C:\Users\igmarco\PycharmProjects\TAUP-DATKit\venv\lib\site-packages\cffi\api.py", line 829, in _load_backend_lib
    raise OSError(msg)
OSError: cannot load library 'libvips-42.dll': error 0x7e.  Additionally, ctypes.util.find_library() did not manage to locate a library called 'libvips-42.dll'
2024-12-19 10:49:06,606 - ERROR - Prueba de log: el logger está configurado correctamente.
2024-12-19 10:49:07,057 - ERROR - Excepción no manejada
Traceback (most recent call last):
  File "C:\Users\igmarco\PycharmProjects\TAUP-DATKit\venv\lib\site-packages\pyvips\__init__.py", line 19, in <module>
    import _libvips
ModuleNotFoundError: No module named '_libvips'

During handling of the above exception, another exception occurred:

Traceback (most recent call last):
  File "C:\Users\igmarco\PycharmProjects\TAUP-DATKit\TAUP_DATKit\Demo\example_process.py", line 3, in <module>
    from TAUP_DATKit.analysis_reporting import generate_pdf_report
  File "C:\Users\igmarco\PycharmProjects\TAUP-DATKit\TAUP_DATKit\analysis_reporting.py", line 5, in <module>
    from TAUP_DATKit.Utils.image_utils import convert_svg_to_png
  File "C:\Users\igmarco\PycharmProjects\TAUP-DATKit\TAUP_DATKit\Utils\image_utils.py", line 1, in <module>
    import pyvips
  File "C:\Users\igmarco\PycharmProjects\TAUP-DATKit\venv\lib\site-packages\pyvips\__init__.py", line 57, in <module>
    vips_lib = ffi.dlopen('libvips-42.dll')
  File "C:\Users\igmarco\PycharmProjects\TAUP-DATKit\venv\lib\site-packages\cffi\api.py", line 150, in dlopen
    lib, function_cache = _make_ffi_library(self, name, flags)
  File "C:\Users\igmarco\PycharmProjects\TAUP-DATKit\venv\lib\site-packages\cffi\api.py", line 834, in _make_ffi_library
    backendlib = _load_backend_lib(backend, libname, flags)
  File "C:\Users\igmarco\PycharmProjects\TAUP-DATKit\venv\lib\site-packages\cffi\api.py", line 829, in _load_backend_lib
    raise OSError(msg)
OSError: cannot load library 'libvips-42.dll': error 0x7e.  Additionally, ctypes.util.find_library() did not manage to locate a library called 'libvips-42.dll'
2024-12-19 10:49:44,242 - ERROR - Prueba de log: el logger está configurado correctamente.
2024-12-19 10:49:44,535 - ERROR - Excepción no manejada
Traceback (most recent call last):
  File "C:\Users\igmarco\PycharmProjects\TAUP-DATKit\venv\lib\site-packages\pyvips\__init__.py", line 19, in <module>
    import _libvips
ModuleNotFoundError: No module named '_libvips'

During handling of the above exception, another exception occurred:

Traceback (most recent call last):
  File "C:\Users\igmarco\PycharmProjects\TAUP-DATKit\TAUP_DATKit\Demo\example_process.py", line 3, in <module>
    from TAUP_DATKit.analysis_reporting import generate_pdf_report
  File "C:\Users\igmarco\PycharmProjects\TAUP-DATKit\TAUP_DATKit\analysis_reporting.py", line 5, in <module>
    from TAUP_DATKit.Utils.image_utils import convert_svg_to_png
  File "C:\Users\igmarco\PycharmProjects\TAUP-DATKit\TAUP_DATKit\Utils\image_utils.py", line 1, in <module>
    import pyvips
  File "C:\Users\igmarco\PycharmProjects\TAUP-DATKit\venv\lib\site-packages\pyvips\__init__.py", line 57, in <module>
    vips_lib = ffi.dlopen('libvips-42.dll')
  File "C:\Users\igmarco\PycharmProjects\TAUP-DATKit\venv\lib\site-packages\cffi\api.py", line 150, in dlopen
    lib, function_cache = _make_ffi_library(self, name, flags)
  File "C:\Users\igmarco\PycharmProjects\TAUP-DATKit\venv\lib\site-packages\cffi\api.py", line 834, in _make_ffi_library
    backendlib = _load_backend_lib(backend, libname, flags)
  File "C:\Users\igmarco\PycharmProjects\TAUP-DATKit\venv\lib\site-packages\cffi\api.py", line 829, in _load_backend_lib
    raise OSError(msg)
OSError: cannot load library 'libvips-42.dll': error 0x7e.  Additionally, ctypes.util.find_library() did not manage to locate a library called 'libvips-42.dll'
2024-12-19 10:51:19,361 - ERROR - Prueba de log: el logger está configurado correctamente.
2024-12-19 10:51:19,663 - ERROR - Excepción no manejada
Traceback (most recent call last):
  File "C:\Users\igmarco\PycharmProjects\TAUP-DATKit\venv\lib\site-packages\pyvips\__init__.py", line 19, in <module>
    import _libvips
ModuleNotFoundError: No module named '_libvips'

During handling of the above exception, another exception occurred:

Traceback (most recent call last):
  File "C:\Users\igmarco\PycharmProjects\TAUP-DATKit\TAUP_DATKit\Demo\example_process.py", line 3, in <module>
    from TAUP_DATKit.analysis_reporting import generate_pdf_report
  File "C:\Users\igmarco\PycharmProjects\TAUP-DATKit\TAUP_DATKit\analysis_reporting.py", line 5, in <module>
    from TAUP_DATKit.Utils.image_utils import convert_svg_to_png
  File "C:\Users\igmarco\PycharmProjects\TAUP-DATKit\TAUP_DATKit\Utils\image_utils.py", line 1, in <module>
    import pyvips
  File "C:\Users\igmarco\PycharmProjects\TAUP-DATKit\venv\lib\site-packages\pyvips\__init__.py", line 57, in <module>
    vips_lib = ffi.dlopen('libvips-42.dll')
  File "C:\Users\igmarco\PycharmProjects\TAUP-DATKit\venv\lib\site-packages\cffi\api.py", line 150, in dlopen
    lib, function_cache = _make_ffi_library(self, name, flags)
  File "C:\Users\igmarco\PycharmProjects\TAUP-DATKit\venv\lib\site-packages\cffi\api.py", line 834, in _make_ffi_library
    backendlib = _load_backend_lib(backend, libname, flags)
  File "C:\Users\igmarco\PycharmProjects\TAUP-DATKit\venv\lib\site-packages\cffi\api.py", line 829, in _load_backend_lib
    raise OSError(msg)
OSError: cannot load library 'libvips-42.dll': error 0x7e.  Additionally, ctypes.util.find_library() did not manage to locate a library called 'libvips-42.dll'
2024-12-19 10:52:39,114 - ERROR - Prueba de log: el logger está configurado correctamente.
2024-12-19 10:53:31,825 - ERROR - Excepción no manejada
Traceback (most recent call last):
  File "C:\Users\igmarco\PycharmProjects\TAUP-DATKit\venv\lib\site-packages\pandas\compat\_optional.py", line 135, in import_optional_dependency
    module = importlib.import_module(name)
  File "C:\Users\igmarco\AppData\Local\Programs\Python\Python39\lib\importlib\__init__.py", line 127, in import_module
    return _bootstrap._gcd_import(name[level:], package, level)
  File "<frozen importlib._bootstrap>", line 1030, in _gcd_import
  File "<frozen importlib._bootstrap>", line 1007, in _find_and_load
  File "<frozen importlib._bootstrap>", line 984, in _find_and_load_unlocked
ModuleNotFoundError: No module named 'openpyxl'

During handling of the above exception, another exception occurred:

Traceback (most recent call last):
  File "C:\Users\igmarco\PycharmProjects\TAUP-DATKit\TAUP_DATKit\Demo\example_process.py", line 52, in <module>
    df_list = load_data(CSV_list, CSV_format_list)
  File "C:\Users\igmarco\PycharmProjects\TAUP-DATKit\TAUP_DATKit\data_loading.py", line 47, in load_data
    df = pd.read_excel(base_file_path, sheet_name=sheet_name, decimal=format_element['decimal'])
  File "C:\Users\igmarco\PycharmProjects\TAUP-DATKit\venv\lib\site-packages\pandas\io\excel\_base.py", line 495, in read_excel
    io = ExcelFile(
  File "C:\Users\igmarco\PycharmProjects\TAUP-DATKit\venv\lib\site-packages\pandas\io\excel\_base.py", line 1567, in __init__
    self._reader = self._engines[engine](
  File "C:\Users\igmarco\PycharmProjects\TAUP-DATKit\venv\lib\site-packages\pandas\io\excel\_openpyxl.py", line 552, in __init__
    import_optional_dependency("openpyxl")
  File "C:\Users\igmarco\PycharmProjects\TAUP-DATKit\venv\lib\site-packages\pandas\compat\_optional.py", line 138, in import_optional_dependency
    raise ImportError(msg)
ImportError: Missing optional dependency 'openpyxl'.  Use pip or conda to install openpyxl.
2024-12-19 11:41:17,735 - ERROR - Prueba de log: el logger está configurado correctamente.
2024-12-19 11:41:18,104 - ERROR - Excepción no manejada
Traceback (most recent call last):
  File "C:\Users\igmarco\PycharmProjects\TAUP-DATKit\TAUP_DATKit\Demo\example_process.py", line 3, in <module>
    from TAUP_DATKit.analysis_reporting import generate_pdf_report
  File "C:\Users\igmarco\PycharmProjects\TAUP-DATKit\TAUP_DATKit\analysis_reporting.py", line 5, in <module>
    from TAUP_DATKit.Utils.image_utils import convert_svg_to_png
  File "C:\Users\igmarco\PycharmProjects\TAUP-DATKit\TAUP_DATKit\Utils\image_utils.py", line 1, in <module>
    import pyvips
ModuleNotFoundError: No module named 'pyvips'
2024-12-19 11:41:34,205 - ERROR - Prueba de log: el logger está configurado correctamente.
2024-12-19 18:04:35,040 - ERROR - Prueba de log: el logger está configurado correctamente.
2024-12-19 18:04:35,041 - ERROR - Prueba de log: el logger está configurado correctamente.
